Workbook

Sheet Sheet1
A1: REnummer | B1: Nätföretag | C1: REnamn | D1: RE | E1: StartHour | F1: EndHour | G1: StartMonth | H1: EndMonth
A2: REL00018 | B2: AB Borlänge Energi Elnät | D2: REL00018 | E2: - | F2: - | G2: - | H2: -
A3: REL00149 | B3: AB PiteEnergi | D3: REL00149 | E3: - | F3: - | G3: - | H3: -
A4: REL00091 | B4: Affärsverken Elnät i Karlskrona AB | D4: REL00091 | E4: - | F4: - | G4: - | H4: -
A5: REL00091 | B5: Affärsverken Karlskrona AB | D5: REL00091 | E5: - | F5: - | G5: - | H5: -
A6: REL00001 | B6: Ale El ek. för. | D6: REL00001 | E6: 6 | F6: 22 | G6: 11 | H6: 3
A7: REL00002 | B7: Alingsås Energi Nät AB | D7: REL00002 | E7: - | F7: - | G7: - | H7: -
A8: REL00003 | B8: Almnäs Bruk AB | D8: REL00003 | E8: - | F8: - | G8: - | H8: -
A9: REL00004 | B9: Alvesta Elnät AB | D9: REL00004 | E9: - | F9: - | G9: - | H9: -
A10: REL00005 | B10: Arvika Teknik AB | D10: REL00005 | E10: - | F10: - | G10: - | H10: -
A11: RER00286 | B11: Baltic Cable AB | D11: RER00286 | E11: - | F11: - | G11: - | H11: -
A12: REL00007 | B12: Bengtsfors Energi Nät AB | D12: REL00007 | E12: - | F12: - | G12: - | H12: -
A13: REL00008 | B13: Bergs Tingslags Elektriska AB | D13: REL00008 | E13: 6 | F13: 21 | G13: 12 | H13: 2
A14: REL00010 | B14: Bjäre Kraft ek. för. | D14: REL00010 | E14: - | F14: - | G14: - | H14: -
A15: REL00011 | B15: Bjärke Energi ek. för. | D15: REL00011 | E15: 6 | F15: 22 | G15: 11 | H15: 3
A16: RER00878 | B16: Bliekevare Nät AB | D16: RER00878 | E16: - | F16: - | G16: - | H16: - | J16: Only customers are themselves, some small number of other customers. No information about tariffs on website
A17: REL00014 | B17: Blåsjön Nät AB | D17: REL00014 | E17: - | F17: - | G17: - | H17: -
A18: REL00015 | B18: Bodens Energi Nät AB | D18: REL00015 | E18: - | F18: - | G18: - | H18: -
A19: REL00016 | B19: Boo Energi ek. för. | D19: REL00016 | E19: 6 | F19: 22 | G19: 11 | H19: 3 | J19: Only for larger electricity customers
A20: REL00017 | B20: Borgholm Energi Elnät AB | D20: REL00017 | E20: - | F20: - | G20: - | H20: -
A21: REL00019 | B21: Borås Elnät AB | D21: REL00019 | E21: 7 | F21: 18 | G21: 11 | H21: 3
A22: REL00101 | B22: Brittedals Elnät AB | D22: REL00101 | E22: - | F22: - | G22: - | H22: -
A23: REL00020 | B23: Brittedals Elnät ek. för. | D23: REL00020 | E23: - | F23: - | G23: - | H23: -
A24: REL01012 | B24: Brittedals Elnät ek. för. | D24: REL01012 | E24: - | F24: - | G24: - | H24: -
A25: RER00932 | B25: Brobacken Nät AB | D25: RER00932 | E25: - | F25: - | G25: - | H25: - | J25: Only customers are themselves
A26: REL00021 | B26: Bromölla Energi och Vatten AB | D26: REL00021 | E26: - | F26: - | G26: - | H26: -
A27: RER01009 | B27: Brännliden Nät AB | D27: RER01009 | E27: - | F27: - | G27: - | H27: - | J27: Only grid for windpower park Brännliden
A28: REL00023 | B28: C4 Elnät AB | D28: REL00023 | E28: - | F28: - | G28: - | H28: - | J28: Power fee incorporated in 1 jan 2026
A29: REL00024 | B29: Carlfors Bruk E Björklund &amp | C29: _ Co KB | D29: REL00024_ Co KB | E29: - | F29: - | G29: - | H29: - | J29: Only for Carlfors industry, no other customers
A30: REL00181 | B30: Dala Elnät AB | D30: REL00181 | E30: 7 | F30: 19 | G30: 11 | H30: 3
A31: REL00869 | B31: Dala Energi Elnät AB | C31: _1_Gagnef Elnät AB | D31: REL00869_1_Gagnef Elnät AB | E31: 7 | F31: 19 | G31: 11 | H31: 3
A32: REL00869 | B32: Dala Energi Elnät AB | C32: _2_Dala Energi Elnät AB | D32: REL00869_2_Dala Energi Elnät AB | E32: 7 | F32: 19 | G32: 11 | H32: 3
A33: REL00869 | B33: Dala Energi Elnät AB | D33: REL00869 | E33: 7 | F33: 19 | G33: 11 | H33: 3
A34: REL03009 | B34: Dala Energi Elnät AB | C34: _f.d. Dala Elnät AB | D34: REL03009_f.d. Dala Elnät AB | E34: 7 | F34: 19 | G34: 11 | H34: 3
A35: REL03009 | B35: Dala Energi Elnät AB | D35: REL03009 | E35: 7 | F35: 19 | G35: 11 | H35: 3
A36: REL00025 | B36: Degerfors Energi AB | D36: REL00025 | E36: 7 | F36: 19 | G36: 11 | H36: 3
A37: REL00094 | B37: E.ON Elnät Kramfors AB | D37: REL00094 | E37: - | F37: - | G37: - | H37: - | J37: No effectavgift, implemented early 2026
A38: REL00571 | B38: E.ON Elnät Stockholm AB | D38: REL00571 | E38: - | F38: - | G38: - | H38: -
A39: REL00601 | B39: E.ON Energidistribution AB | C39: _5_Nord | D39: REL00601_5_Nord | E39: - | F39: - | G39: - | H39: -
A40: REL00601 | B40: E.ON Energidistribution AB | C40: _6_Nord | D40: REL00601_6_Nord | E40: - | F40: - | G40: - | H40: -
...

Sheet filteredHighloadTime
A1: REnummer | B1: Nätföretag | C1: REnamn | D1: RE | E1: StartHour | F1: EndHour | G1: StartMonth | H1: EndMonth
A2: =_xlfn.XLOOKUP($D2, Sheet1!$D:$D, Sheet1!A:A, "") -> REL00018 | B2: =_xlfn.XLOOKUP($D2, Sheet1!$D:$D, Sheet1!B:B, "") -> AB Borlänge Energi Elnät | C2: =_xlfn.XLOOKUP($D2, Sheet1!$D:$D, Sheet1!C:C, "") -> 0 | D2: REL00018 | E2: =_xlfn.XLOOKUP($D2, Sheet1!$D:$D, Sheet1!E:E, "") -> - | F2: =_xlfn.XLOOKUP($D2, Sheet1!$D:$D, Sheet1!F:F, "") -> - | G2: =_xlfn.XLOOKUP($D2, Sheet1!$D:$D, Sheet1!G:G, "") -> - | H2: =_xlfn.XLOOKUP($D2, Sheet1!$D:$D, Sheet1!H:H, "") -> -
A3: =_xlfn.XLOOKUP($D3, Sheet1!$D:$D, Sheet1!A:A, "") -> REL00149 | B3: =_xlfn.XLOOKUP($D3, Sheet1!$D:$D, Sheet1!B:B, "") -> AB PiteEnergi | C3: =_xlfn.XLOOKUP($D3, Sheet1!$D:$D, Sheet1!C:C, "") -> 0 | D3: REL00149 | E3: =_xlfn.XLOOKUP($D3, Sheet1!$D:$D, Sheet1!E:E, "") -> - | F3: =_xlfn.XLOOKUP($D3, Sheet1!$D:$D, Sheet1!F:F, "") -> - | G3: =_xlfn.XLOOKUP($D3, Sheet1!$D:$D, Sheet1!G:G, "") -> - | H3: =_xlfn.XLOOKUP($D3, Sheet1!$D:$D, Sheet1!H:H, "") -> -
A4: =_xlfn.XLOOKUP($D4, Sheet1!$D:$D, Sheet1!A:A, "") -> REL00091 | B4: =_xlfn.XLOOKUP($D4, Sheet1!$D:$D, Sheet1!B:B, "") -> Affärsverken Elnät i Karlskrona AB | C4: =_xlfn.XLOOKUP($D4, Sheet1!$D:$D, Sheet1!C:C, "") -> 0 | D4: REL00091 | E4: =_xlfn.XLOOKUP($D4, Sheet1!$D:$D, Sheet1!E:E, "") -> - | F4: =_xlfn.XLOOKUP($D4, Sheet1!$D:$D, Sheet1!F:F, "") -> - | G4: =_xlfn.XLOOKUP($D4, Sheet1!$D:$D, Sheet1!G:G, "") -> - | H4: =_xlfn.XLOOKUP($D4, Sheet1!$D:$D, Sheet1!H:H, "") -> -
A5: =_xlfn.XLOOKUP($D5, Sheet1!$D:$D, Sheet1!A:A, "") -> REL00001 | B5: =_xlfn.XLOOKUP($D5, Sheet1!$D:$D, Sheet1!B:B, "") -> Ale El ek. för. | C5: =_xlfn.XLOOKUP($D5, Sheet1!$D:$D, Sheet1!C:C, "") -> 0 | D5: REL00001 | E5: =_xlfn.XLOOKUP($D5, Sheet1!$D:$D, Sheet1!E:E, "") -> 6 | F5: =_xlfn.XLOOKUP($D5, Sheet1!$D:$D, Sheet1!F:F, "") -> 22 | G5: =_xlfn.XLOOKUP($D5, Sheet1!$D:$D, Sheet1!G:G, "") -> 11 | H5: =_xlfn.XLOOKUP($D5, Sheet1!$D:$D, Sheet1!H:H, "") -> 3
A6: =_xlfn.XLOOKUP($D6, Sheet1!$D:$D, Sheet1!A:A, "") -> REL00002 | B6: =_xlfn.XLOOKUP($D6, Sheet1!$D:$D, Sheet1!B:B, "") -> Alingsås Energi Nät AB | C6: =_xlfn.XLOOKUP($D6, Sheet1!$D:$D, Sheet1!C:C, "") -> 0 | D6: REL00002 | E6: =_xlfn.XLOOKUP($D6, Sheet1!$D:$D, Sheet1!E:E, "") -> - | F6: =_xlfn.XLOOKUP($D6, Sheet1!$D:$D, Sheet1!F:F, "") -> - | G6: =_xlfn.XLOOKUP($D6, Sheet1!$D:$D, Sheet1!G:G, "") -> - | H6: =_xlfn.XLOOKUP($D6, Sheet1!$D:$D, Sheet1!H:H, "") -> -
A7: =_xlfn.XLOOKUP($D7, Sheet1!$D:$D, Sheet1!A:A, "") -> REL00003 | B7: =_xlfn.XLOOKUP($D7, Sheet1!$D:$D, Sheet1!B:B, "") -> Almnäs Bruk AB | C7: =_xlfn.XLOOKUP($D7, Sheet1!$D:$D, Sheet1!C:C, "") -> 0 | D7: REL00003 | E7: =_xlfn.XLOOKUP($D7, Sheet1!$D:$D, Sheet1!E:E, "") -> - | F7: =_xlfn.XLOOKUP($D7, Sheet1!$D:$D, Sheet1!F:F, "") -> - | G7: =_xlfn.XLOOKUP($D7, Sheet1!$D:$D, Sheet1!G:G, "") -> - | H7: =_xlfn.XLOOKUP($D7, Sheet1!$D:$D, Sheet1!H:H, "") -> -
A8: =_xlfn.XLOOKUP($D8, Sheet1!$D:$D, Sheet1!A:A, "") -> REL00004 | B8: =_xlfn.XLOOKUP($D8, Sheet1!$D:$D, Sheet1!B:B, "") -> Alvesta Elnät AB | C8: =_xlfn.XLOOKUP($D8, Sheet1!$D:$D, Sheet1!C:C, "") -> 0 | D8: REL00004 | E8: =_xlfn.XLOOKUP($D8, Sheet1!$D:$D, Sheet1!E:E, "") -> - | F8: =_xlfn.XLOOKUP($D8, Sheet1!$D:$D, Sheet1!F:F, "") -> - | G8: =_xlfn.XLOOKUP($D8, Sheet1!$D:$D, Sheet1!G:G, "") -> - | H8: =_xlfn.XLOOKUP($D8, Sheet1!$D:$D, Sheet1!H:H, "") -> -
A9: =_xlfn.XLOOKUP($D9, Sheet1!$D:$D, Sheet1!A:A, "") -> REL00005 | B9: =_xlfn.XLOOKUP($D9, Sheet1!$D:$D, Sheet1!B:B, "") -> Arvika Teknik AB | C9: =_xlfn.XLOOKUP($D9, Sheet1!$D:$D, Sheet1!C:C, "") -> 0 | D9: REL00005 | E9: =_xlfn.XLOOKUP($D9, Sheet1!$D:$D, Sheet1!E:E, "") -> - | F9: =_xlfn.XLOOKUP($D9, Sheet1!$D:$D, Sheet1!F:F, "") -> - | G9: =_xlfn.XLOOKUP($D9, Sheet1!$D:$D, Sheet1!G:G, "") -> - | H9: =_xlfn.XLOOKUP($D9, Sheet1!$D:$D, Sheet1!H:H, "") -> -
A10: =_xlfn.XLOOKUP($D10, Sheet1!$D:$D, Sheet1!A:A, "") -> RER00286 | B10: =_xlfn.XLOOKUP($D10, Sheet1!$D:$D, Sheet1!B:B, "") -> Baltic Cable AB | C10: =_xlfn.XLOOKUP($D10, Sheet1!$D:$D, Sheet1!C:C, "") -> 0 | D10: RER00286 | E10: =_xlfn.XLOOKUP($D10, Sheet1!$D:$D, Sheet1!E:E, "") -> - | F10: =_xlfn.XLOOKUP($D10, Sheet1!$D:$D, Sheet1!F:F, "") -> - | G10: =_xlfn.XLOOKUP($D10, Sheet1!$D:$D, Sheet1!G:G, "") -> - | H10: =_xlfn.XLOOKUP($D10, Sheet1!$D:$D, Sheet1!H:H, "") -> -
A11: =_xlfn.XLOOKUP($D11, Sheet1!$D:$D, Sheet1!A:A, "") -> REL00007 | B11: =_xlfn.XLOOKUP($D11, Sheet1!$D:$D, Sheet1!B:B, "") -> Bengtsfors Energi Nät AB | C11: =_xlfn.XLOOKUP($D11, Sheet1!$D:$D, Sheet1!C:C, "") -> 0 | D11: REL00007 | E11: =_xlfn.XLOOKUP($D11, Sheet1!$D:$D, Sheet1!E:E, "") -> - | F11: =_xlfn.XLOOKUP($D11, Sheet1!$D:$D, Sheet1!F:F, "") -> - | G11: =_xlfn.XLOOKUP($D11, Sheet1!$D:$D, Sheet1!G:G, "") -> - | H11: =_xlfn.XLOOKUP($D11, Sheet1!$D:$D, Sheet1!H:H, "") -> -
A12: =_xlfn.XLOOKUP($D12, Sheet1!$D:$D, Sheet1!A:A, "") -> REL00008 | B12: =_xlfn.XLOOKUP($D12, Sheet1!$D:$D, Sheet1!B:B, "") -> Bergs Tingslags Elektriska AB | C12: =_xlfn.XLOOKUP($D12, Sheet1!$D:$D, Sheet1!C:C, "") -> 0 | D12: REL00008 | E12: =_xlfn.XLOOKUP($D12, Sheet1!$D:$D, Sheet1!E:E, "") -> 6 | F12: =_xlfn.XLOOKUP($D12, Sheet1!$D:$D, Sheet1!F:F, "") -> 21 | G12: =_xlfn.XLOOKUP($D12, Sheet1!$D:$D, Sheet1!G:G, "") -> 12 | H12: =_xlfn.XLOOKUP($D12, Sheet1!$D:$D, Sheet1!H:H, "") -> 2
A13: =_xlfn.XLOOKUP($D13, Sheet1!$D:$D, Sheet1!A:A, "") -> REL00010 | B13: =_xlfn.XLOOKUP($D13, Sheet1!$D:$D, Sheet1!B:B, "") -> Bjäre Kraft ek. för. | C13: =_xlfn.XLOOKUP($D13, Sheet1!$D:$D, Sheet1!C:C, "") -> 0 | D13: REL00010 | E13: =_xlfn.XLOOKUP($D13, Sheet1!$D:$D, Sheet1!E:E, "") -> - | F13: =_xlfn.XLOOKUP($D13, Sheet1!$D:$D, Sheet1!F:F, "") -> - | G13: =_xlfn.XLOOKUP($D13, Sheet1!$D:$D, Sheet1!G:G, "") -> - | H13: =_xlfn.XLOOKUP($D13, Sheet1!$D:$D, Sheet1!H:H, "") -> -
... A307: =_xlfn.XLOOKUP($D307, Sheet1!$D:$D, Sheet1!A:A, "") -> REL00257 | B307: =_xlfn.XLOOKUP($D307, Sheet1!$D:$D, Sheet1!B:B, "") -> Övik Energi Nät AB | C307: =_xlfn.XLOOKUP($D307, Sheet1!$D:$D, Sheet1!C:C, "") -> 0 | D307: REL00257 | E307: =_xlfn.XLOOKUP($D307, Sheet1!$D:$D, Sheet1!E:E, "") -> - | F307: =_xlfn.XLOOKUP($D307, Sheet1!$D:$D, Sheet1!F:F, "") -> - | G307: =_xlfn.XLOOKUP($D307, Sheet1!$D:$D, Sheet1!G:G, "") -> - | H307: =_xlfn.XLOOKUP($D307, Sheet1!$D:$D, Sheet1!H:H, "") -> -
A308: =_xlfn.XLOOKUP($D308, Sheet1!$D:$D, Sheet1!A:A, "") | B308: =_xlfn.XLOOKUP($D308, Sheet1!$D:$D, Sheet1!B:B, "") | C308: =_xlfn.XLOOKUP($D308, Sheet1!$D:$D, Sheet1!C:C, "") | D308: 0 | E308: =_xlfn.XLOOKUP($D308, Sheet1!$D:$D, Sheet1!E:E, "") | F308: =_xlfn.XLOOKUP($D308, Sheet1!$D:$D, Sheet1!F:F, "") | G308: =_xlfn.XLOOKUP($D308, Sheet1!$D:$D, Sheet1!G:G, "") | H308: =_xlfn.XLOOKUP($D308, Sheet1!$D:$D, Sheet1!H:H, "")
