Workbook

Sheet Data
A1: länskod | B1: län | C1: kommunkod | D1: kommunnamn | E1: KONCESSION | F1: Spanning | G1: Enhet | H1: Subredovisningsenhet (2023) | I1: Subredovisningsenhet (2022) | J1: Subredovisningsenhet (2021) | K1: Subredovisningsenhet (2020) | L1: Subredovisningsenhet (2019) | M1: FöretagNa | N1: elomrade
A2: 25 | B2: Norrbotten | C2: 2584 | D2: Kiruna | E2: 8600S | F2: 20 | G2: REL03030 | H2: REL03030_1_Lokalnät Norr | I2: REL00572 | J2: REL00572 | K2: REL00572 | L2: REL00572 | M2: Vattenfall Eldistribution AB | N2: SE1
A3: 25 | B3: Norrbotten | C3: 2510 | D3: Jokkmokk | E3: 8600B | F3: 20 | G3: REL03030 | H3: REL03030_1_Lokalnät Norr | I3: REL00572 | J3: REL00572 | K3: REL00572 | L3: REL00572 | M3: Vattenfall Eldistribution AB | N3: SE1
A4: 23 | B4: Jämtland | C4: 2361 | D4: Härjedalen | E4: 1952EA | F4: 52 | G4: REL00576 | H4: REL00576_3 | M4: Härjeåns Nät AB | N4: SE2
A5: 25 | B5: Norrbotten | C5: 2523 | D5: Gällivare | E5: 8600K | F5: 20 | G5: REL03030 | H5: REL03030_1_Lokalnät Norr | I5: REL00572 | J5: REL00572 | K5: REL00572 | L5: REL00572 | M5: Vattenfall Eldistribution AB | N5: SE1
A6: 20 | B6: Dalarna | C6: 2039 | D6: Älvdalen | E6: 1517DP | F6: 20 | G6: REL03035 | H6: REL03035_1_Mellansverige | I6: REL03017_2_Västra Svealand | J6: REL03017_2_Västra Svealand | K6: REL03017_2_Västra Svealand | L6: REL03008_2_Västra Svealand | M6: Ellevio AB | N6: SE3
A7: 09 | B7: Gotland | C7: 0980 | D7: Gotland | E7: 2118BG | F7: 70 | G7: REL00945 | H7: REL00945 | M7: Gotlands Elnät AB | N7: SE3
A8: 25 | B8: Norrbotten | C8: 2506 | D8: Arjeplog | E8: 8600F | F8: 20 | G8: REL03030 | H8: REL03030_1_Lokalnät Norr | I8: REL00572 | J8: REL00572 | K8: REL00572 | L8: REL00572 | M8: Vattenfall Eldistribution AB | N8: SE1
A9: 23 | B9: Jämtland | C9: 2313 | D9: Strömsund | E9: 406GU | F9: 20 | G9: REL03028 | H9: REL03028_3_Stockholm | M9: E.ON Energidistribution AB | N9: SE2
A10: 22 | B10: Västernorrland | C10: 2283 | D10: Sollefteå | E10: 406GU | F10: 20 | G10: REL03028 | H10: REL03028_3_Stockholm | M10: E.ON Energidistribution AB | N10: SE2
A11: 12 | B11: Skåne | C11: 1262 | D11: Lomma | E11: 11213 | F11: 24 | G11: REL00886 | H11: REL00886_1_Höörs kommun | M11: Kraftringen Nät AB | N11: SE4
A12: 24 | B12: Västerbotten | C12: 2482 | D12: Skellefteå | E12: 412KC | F12: 20 | G12: REL00824 | H12: REL00824 | M12: Skellefteå Kraft Elnät AB | N12: SE1
A13: 24 | B13: Västerbotten | C13: 2462 | D13: Vilhelmina | E13: 8600N | F13: 22 | G13: REL03030 | H13: REL03030_1_Lokalnät Norr | I13: REL00572 | J13: REL00572 | K13: REL00572 | L13: REL00572 | M13: Vattenfall Eldistribution AB | N13: SE2
A14: 22 | B14: Västernorrland | C14: 2284 | D14: Örnsköldsvik | E14: 8600Q | F14: 20 | G14: REL03030 | H14: REL03030_1_Lokalnät Norr | I14: REL00572 | J14: REL00572 | K14: REL00572 | L14: REL00572 | M14: Vattenfall Eldistribution AB | N14: SE2
A15: 23 | B15: Jämtland | C15: 2321 | D15: Åre | E15: 4CH | F15: 40 | G15: REL00085 | H15: REL00085 | M15: Jämtkraft Elnät AB | N15: SE2
A16: 24 | B16: Västerbotten | C16: 2421 | D16: Storuman | E16: 8600N | F16: 22 | G16: REL03030 | H16: REL03030_1_Lokalnät Norr | I16: REL00572 | J16: REL00572 | K16: REL00572 | L16: REL00572 | M16: Vattenfall Eldistribution AB | N16: SE2
A17: 25 | B17: Norrbotten | C17: 2581 | D17: Piteå | E17: 1834AE | F17: 20 | G17: REL00149 | H17: REL00149 | M17: AB PiteEnergi | N17: SE1
A18: 25 | B18: Norrbotten | C18: 2521 | D18: Pajala | E18: 8600L | F18: 20 | G18: REL03030 | H18: REL03030_1_Lokalnät Norr | I18: REL00572 | J18: REL00572 | K18: REL00572 | L18: REL00572 | M18: Vattenfall Eldistribution AB | N18: SE1
A19: 24 | B19: Västerbotten | C19: 2422 | D19: Sorsele | E19: 8600N | F19: 22 | G19: REL03030 | H19: REL03030_1_Lokalnät Norr | I19: REL00572 | J19: REL00572 | K19: REL00572 | L19: REL00572 | M19: Vattenfall Eldistribution AB | N19: SE2
A20: 01 | B20: Stockholm | C20: 0184 | D20: Solna | E20: 8300A | F20: 70 | G20: REL03030 | H20: REL03030_1_Lokalnät Norr | I20: REL00572 | J20: REL00572 | K20: REL00572 | L20: REL00572 | M20: Vattenfall Eldistribution AB | N20: SE3
A21: 23 | B21: Jämtland | C21: 2309 | D21: Krokom | E21: 4CH | F21: 40 | G21: REL00085 | H21: REL00085 | M21: Jämtkraft Elnät AB | N21: SE2
A22: 21 | B22: Gävleborg | C22: 2161 | D22: Ljusdal | E22: 35CR | F22: 24 | G22: REL03035 | H22: REL03035_1_Mellansverige | I22: REL03017_2_Västra Svealand | J22: REL03017_2_Västra Svealand | K22: REL03017_2_Västra Svealand | L22: REL03008_2_Västra Svealand | M22: Ellevio AB | N22: SE2
A23: 23 | B23: Jämtland | C23: 2326 | D23: Berg | E23: 10870 | F23: 52 | G23: REL00008 | H23: REL00008 | M23: Bergs Tingslags Elektriska AB | N23: SE2
A24: 25 | B24: Norrbotten | C24: 2505 | D24: Arvidsjaur | E24: 8600I | F24: 20 | G24: REL03030 | H24: REL03030_1_Lokalnät Norr | I24: REL00572 | J24: REL00572 | K24: REL00572 | L24: REL00572 | M24: Vattenfall Eldistribution AB | N24: SE1
A25: 01 | B25: Stockholm | C25: 0188 | D25: Norrtälje | E25: 5259L | F25: 25 | G25: REL03030 | H25: REL03030_1_Lokalnät Norr | I25: REL00572 | J25: REL00572 | K25: REL00572 | L25: REL00572 | M25: Vattenfall Eldistribution AB | N25: SE3
A26: 24 | B26: Västerbotten | C26: 2481 | D26: Lycksele | E26: 1698AB | F26: 20 | G26: REL00824 | H26: REL00824 | M26: Skellefteå Kraft Elnät AB | N26: SE2
A27: 24 | B27: Västerbotten | C27: 2463 | D27: Åsele | E27: 8600N | F27: 22 | G27: REL03030 | H27: REL03030_1_Lokalnät Norr | I27: REL00572 | J27: REL00572 | K27: REL00572 | L27: REL00572 | M27: Vattenfall Eldistribution AB | N27: SE2
A28: 24 | B28: Västerbotten | C28: 2480 | D28: Umeå | E28: 72JA | F28: 52 | G28: REL00584 | H28: REL00584 | M28: Umeå Energi Elnät AB | N28: SE2
A29: 25 | B29: Norrbotten | C29: 2580 | D29: Luleå | E29: 104FA | F29: 40 | G29: REL00118 | H29: REL00118 | M29: Luleå Energi Elnät AB | N29: SE1
A30: 21 | B30: Gävleborg | C30: 2184 | D30: Hudiksvall | E30: 35CR | F30: 24 | G30: REL03035 | H30: REL03035_1_Mellansverige | I30: REL03017_2_Västra Svealand | J30: REL03017_2_Västra Svealand | K30: REL03017_2_Västra Svealand | L30: REL03008_2_Västra Svealand | M30: Ellevio AB | N30: SE2
A31: 22 | B31: Västernorrland | C31: 2281 | D31: Sundsvall | E31: 380CIB | F31: 20 | G31: REL03028 | H31: REL03028_3_Stockholm | M31: E.ON Energidistribution AB | N31: SE2
A32: 17 | B32: Värmland | C32: 1737 | D32: Torsby | E32: 7220EI | F32: 24 | G32: REL03035 | H32: REL03035_1_Mellansverige | I32: REL03017_2_Västra Svealand | J32: REL03017_2_Västra Svealand | K32: REL03017_2_Västra Svealand | L32: REL03008_2_Västra Svealand | M32: Ellevio AB | N32: SE3
A33: 20 | B33: Dalarna | C33: 2023 | D33: Malung-Sälen | E33: 11116 | F33: 36 | G33: REL00123 | H33: REL00123 | M33: Malung-Sälens Elnät AB | N33: SE3
A34: 25 | B34: Norrbotten | C34: 2582 | D34: Boden | E34: 294IT | F34: 20 | G34: REL00015 | H34: REL00015 | M34: Bodens Energi Nät AB | N34: SE1
A35: 23 | B35: Jämtland | C35: 2305 | D35: Bräcke | E35: 1952EA | F35: 52 | G35: REL00576 | H35: REL00576_3 | M35: Härjeåns Nät AB | N35: SE2
A36: 25 | B36: Norrbotten | C36: 2514 | D36: Kalix | E36: 8600R | F36: 20 | G36: REL03030 | H36: REL03030_1_Lokalnät Norr | I36: REL00572 | J36: REL00572 | K36: REL00572 | L36: REL00572 | M36: Vattenfall Eldistribution AB | N36: SE1
A37: 03 | B37: Uppsala | C37: 0382 | D37: Östhammar | E37: 731ÖGR | F37: 20 | G37: REL03030 | H37: REL03030_1_Lokalnät Norr | I37: REL00572 | J37: REL00572 | K37: REL00572 | L37: REL00572 | M37: Vattenfall Eldistribution AB | N37: SE3
A38: 08 | B38: Kalmar | C38: 0885 | D38: Borgholm | E38: 380Bm | F38: 20 | G38: REL03028 | H38: REL03028_3_Stockholm | M38: E.ON Energidistribution AB | N38: SE4
A39: 08 | B39: Kalmar | C39: 0840 | D39: Mörbylånga | E39: 380Bm | F39: 20 | G39: REL03028 | H39: REL03028_3_Stockholm | M39: E.ON Energidistribution AB | N39: SE4
A40: 08 | B40: Kalmar | C40: 0883 | D40: Västervik | E40: 380CPG | F40: 20 | G40: REL03028 | H40: REL03028_3_Stockholm | M40: E.ON Energidistribution AB | N40: SE3
...

Sheet ModelingAreas
A1: Stockholm | B1: Uppsala | C1: Södermanland | D1: Östergötland | E1: Jönköping | F1: Kronoberg | G1: Kalmar | H1: Gotland | I1: Blekinge | J1: Skåne | K1: Halland | L1: Västra Götaland | M1: Värmland | N1: Örebro | O1: Västmanland | P1: Dalarna | Q1: Gävleborg | R1: Västernorrland | S1: Jämtland | T1: Västerbotten | U1: Norrbotten | V1: SE1 | W1: SE2 | X1: SE3 | Y1: SE4 | Z1: Sverige
A2: {=_xlfn._xlws.FILTER(Data!$D:$D, Data!$B:$B = A$1)} -> Solna | B2: {=_xlfn._xlws.FILTER(Data!$D:$D, Data!$B:$B = B$1)} -> Östhammar | C2: {=_xlfn._xlws.FILTER(Data!$D:$D, Data!$B:$B = C$1)} -> Nyköping | D2: {=_xlfn._xlws.FILTER(Data!$D:$D, Data!$B:$B = D$1)} -> Valdemarsvik | E2: {=_xlfn._xlws.FILTER(Data!$D:$D, Data!$B:$B = E$1)} -> Jönköping | F2: {=_xlfn._xlws.FILTER(Data!$D:$D, Data!$B:$B = F$1)} -> Ljungby | G2: {=_xlfn._xlws.FILTER(Data!$D:$D, Data!$B:$B = G$1)} -> Borgholm | H2: {=_xlfn._xlws.FILTER(Data!$D:$D, Data!$B:$B = H$1)} -> Gotland | ... U2: {=_xlfn._xlws.FILTER(Data!$D:$D, Data!$B:$B = U$1)} -> Kiruna | V2: {=_xlfn._xlws.FILTER(Data!$D:$D, Data!$J:$J = V$1)} -> #VALUE! | W2: {=_xlfn._xlws.FILTER(Data!$D:$D, Data!$J:$J = W$1)} -> #VALUE! | X2: {=_xlfn._xlws.FILTER(Data!$D:$D, Data!$J:$J = X$1)} -> #VALUE! | Y2: {=_xlfn._xlws.FILTER(Data!$D:$D, Data!$J:$J = Y$1)} -> #VALUE! | Z2: {=_xlfn._xlws.FILTER(Data!$D:$D, (NOT(ISBLANK(Data!$D:$D)))*(Data!$D:$D <> "kommunnamn"))} -> Kiruna
A3: Norrtälje | B3: Tierp | C3: Eskilstuna | D3: Norrköping | E3: Vetlanda | F3: Växjö | G3: Mörbylånga | I3: Sölvesborg | J3: Burlöv | K3: Varberg | L3: Mariestad | M3: Säffle | N3: Örebro | O3: Sala | P3: Malung-Sälen | Q3: Hudiksvall | R3: Örnsköldsvik | S3: Strömsund | T3: Vilhelmina | U3: Jokkmokk | Z3: Jokkmokk
A4: Värmdö | B4: Uppsala | C4: Katrineholm | D4: Vadstena | E4: Värnamo | F4: Uppvidinge | G4: Västervik | I4: Ronneby | J4: Kristianstad | K4: Halmstad | L4: Strömstad | M4: Hagfors | N4: Lindesberg | O4: Skinnskatteberg | P4: Mora | Q4: Gävle | R4: Sundsvall | S4: Åre | T4: Storuman | U4: Gällivare | Z4: Härjedalen
A5: Sundbyberg | B5: Enköping | C5: Strängnäs | D5: Linköping | E5: Gislaved | F5: Tingsryd | G5: Oskarshamn | I5: Karlshamn | J5: Hässleholm | K5: Laholm | L5: Lidköping | M5: Arvika | N5: Askersund | O5: Köping | P5: Falun | Q5: Nordanstig | R5: Ånge | S5: Krokom | T5: Sorsele | U5: Arjeplog | Z5: Gällivare
A6: Haninge | B6: Heby | C6: Flen | D6: Söderköping | E6: Nässjö | F6: Alvesta | G6: Kalmar | I6: Olofström | J6: Simrishamn | K6: Kungsbacka | L6: Mellerud | M6: Filipstad | N6: Laxå | O6: Hallstahammar | P6: Rättvik | Q6: Söderhamn | R6: Kramfors | S6: Berg | T6: Lycksele | U6: Piteå | Z6: Älvdalen
A7: Upplands-Bro | B7: Älvkarleby | C7: Oxelösund | D7: Kinda | E7: Eksjö | F7: Älmhult | G7: Mönsterås | J7: Ystad | K7: Hylte | L7: Stenungsund | M7: Sunne | N7: Nora | O7: Norberg | P7: Orsa | Q7: Ovanåker | R7: Härnösand | S7: Bräcke | T7: Åsele | U7: Pajala | Z7: Gotland
A8: Nynäshamn | B8: Håbo | C8: Trosa | D8: Motala | E8: Vaggeryd | F8: Markaryd | G8: Vimmerby | J8: Trelleborg | L8: Ulricehamn | M8: Årjäng | N8: Hallsberg | O8: Arboga | P8: Vansbro | Q8: Bollnäs | R8: Timrå | S8: Ragunda | T8: Umeå | U8: Arvidsjaur | Z8: Arjeplog
A9: Södertälje | B9: Knivsta | C9: Gnesta | D9: Finspång | E9: Sävsjö | F9: Lessebo | G9: Nybro | J9: Båstad | L9: Falköping | M9: Kristinehamn | N9: Ljusnarsberg | O9: Surahammar | P9: Ludvika | Q9: Sandviken | S9: Östersund | T9: Dorotea | U9: Luleå | Z9: Strömsund
A10: Österåker | C10: Vingåker | D10: Ödeshög | E10: Aneby | G10: Hultsfred | J10: Vellinge | L10: Bengtsfors | M10: Karlstad | N10: Degerfors | O10: Fagersta | P10: Gagnef | Q10: Ockelbo | T10: Vindeln | U10: Boden | Z10: Sollefteå
A11: Nykvarn | D11: Åtvidaberg | E11: Habo | G11: Högsby | J11: Höganäs | L11: Åmål | M11: Eda | N11: Karlskoga | O11: Kungsör | P11: Leksand | Q11: Hofors | T11: Nordmaling | U11: Kalix | Z11: Lomma
A12: Ekerö | D12: Ydre | E12: Gnosjö | G12: Emmaboda | J12: Bromölla | L12: Göteborg | M12: Grums | N12: Lekeberg | P12: Hedemora | T12: Robertsfors | U12: Överkalix | Z12: Skellefteå
A13: Vallentuna | D13: Boxholm | E13: Tranås | G13: Torsås | J13: Osby | L13: Mark | M13: Storfors | N13: Kumla | P13: Smedjebacken | T13: Norsjö | U13: Övertorneå | Z13: Vilhelmina
A14: Sigtuna | D14: Mjölby | E14: Mullsjö | J14: Skurup | L14: Orust | M14: Hammarö | P14: Avesta | T14: Malå | U14: Haparanda | Z14: Örnsköldsvik
A15: Botkyrka | J15: Sjöbo | L15: Svenljunga | M15: Kil | P15: Säter | T15: Bjurholm | U15: Älvsbyn | Z15: Åre
A16: Huddinge | J16: Ängelholm | L16: Tjörn | M16: Forshaga | P16: Borlänge | T16: Vännäs | Z16: Storuman
A17: Stockholm | J17: Östra Göinge | L17: Borås | M17: Munkfors | Z17: Piteå
A18: Nacka | J18: Perstorp | L18: Vänersborg | Z18: Pajala
A19: Vaxholm | J19: Hörby | L19: Dals-Ed | Z19: Sorsele
A20: Tyresö | J20: Lund | L20: Karlsborg | Z20: Solna
A21: Upplands Väsby | J21: Eslöv | L21: Tranemo | Z21: Krokom
A22: Salem | J22: Helsingborg | L22: Uddevalla | Z22: Ljusdal
A23: Täby | J23: Tomelilla | L23: Vara | Z23: Berg
A24: Järfälla | J24: Svalöv | L24: Lysekil | Z24: Arvidsjaur
A25: Sollentuna | J25: Klippan | L25: Sotenäs | Z25: Norrtälje
A26: Lidingö | J26: Malmö | L26: Skövde | Z26: Lycksele
A27: Danderyd | J27: Örkelljunga | L27: Kungälv | Z27: Åsele
J28: Höör | L28: Munkedal | Z28: Umeå
J29: Landskrona | L29: Götene | Z29: Luleå
J30: Kävlinge | L30: Färgelanda | Z30: Hudiksvall
J31: Svedala | L31: Töreboda | Z31: Sundsvall
J32: Bjuv | L32: Hjo | Z32: Torsby
J33: Staffanstorp | L33: Gullspång | Z33: Malung-Sälen
J34: Åstorp | L34: Tidaholm | Z34: Boden
L35: Öckerö | Z35: Bräcke
L36: Alingsås | Z36: Kalix
L37: Herrljunga | Z37: Östhammar
L38: Skara | Z38: Borgholm
L39: Vårgårda | Z39: Mörbylånga
L40: Mölndal | Z40: Västervik
...
